[2023-04-07T13:37:58.415+0000] {taskinstance.py:1090} INFO - Dependencies all met for dep_context=non-requeueable deps ti=<TaskInstance: dag_with_posgres_operator_v02.insert_into_table scheduled__2023-04-01T00:00:00+00:00 [queued]>
[2023-04-07T13:37:58.430+0000] {taskinstance.py:1090} INFO - Dependencies all met for dep_context=requeueable deps ti=<TaskInstance: dag_with_posgres_operator_v02.insert_into_table scheduled__2023-04-01T00:00:00+00:00 [queued]>
[2023-04-07T13:37:58.430+0000] {taskinstance.py:1288} INFO - 
--------------------------------------------------------------------------------
[2023-04-07T13:37:58.431+0000] {taskinstance.py:1289} INFO - Starting attempt 1 of 6
[2023-04-07T13:37:58.431+0000] {taskinstance.py:1290} INFO - 
--------------------------------------------------------------------------------
[2023-04-07T13:37:58.460+0000] {taskinstance.py:1309} INFO - Executing <Task(PostgresOperator): insert_into_table> on 2023-04-01 00:00:00+00:00
[2023-04-07T13:37:58.464+0000] {standard_task_runner.py:55} INFO - Started process 1599 to run task
[2023-04-07T13:37:58.466+0000] {standard_task_runner.py:82} INFO - Running: ['***', 'tasks', 'run', 'dag_with_posgres_operator_v02', 'insert_into_table', 'scheduled__2023-04-01T00:00:00+00:00', '--job-id', '6819', '--raw', '--subdir', 'DAGS_FOLDER/dag_with_postgres_operator.py', '--cfg-path', '/tmp/tmp112w12en']
[2023-04-07T13:37:58.470+0000] {standard_task_runner.py:83} INFO - Job 6819: Subtask insert_into_table
[2023-04-07T13:37:58.596+0000] {task_command.py:389} INFO - Running <TaskInstance: dag_with_posgres_operator_v02.insert_into_table scheduled__2023-04-01T00:00:00+00:00 [running]> on host ce9c8327347b
[2023-04-07T13:37:58.654+0000] {abstractoperator.py:615} ERROR - Exception rendering Jinja template for task 'insert_into_table', field 'sql'. Template: "\n            insert into dag_runs (dt, dag_id) values ('{{ dt }}', '{{ dag.dag_id }}')\n        "
Traceback (most recent call last):
  File "/home/airflow/.local/lib/python3.7/site-packages/airflow/models/abstractoperator.py", line 607, in _do_render_template_fields
    seen_oids,
  File "/home/airflow/.local/lib/python3.7/site-packages/airflow/models/abstractoperator.py", line 665, in render_template
    return render_template_to_string(template, context)
  File "/home/airflow/.local/lib/python3.7/site-packages/airflow/utils/helpers.py", line 288, in render_template_to_string
    return render_template(template, cast(MutableMapping[str, Any], context), native=False)
  File "/home/airflow/.local/lib/python3.7/site-packages/airflow/utils/helpers.py", line 283, in render_template
    return "".join(nodes)
  File "<template>", line 14, in root
  File "/home/airflow/.local/lib/python3.7/site-packages/jinja2/runtime.py", line 852, in _fail_with_undefined_error
    raise self._undefined_exception(self._undefined_message)
jinja2.exceptions.UndefinedError: 'dt' is undefined
[2023-04-07T13:37:58.656+0000] {taskinstance.py:1776} ERROR - Task failed with exception
Traceback (most recent call last):
  File "/home/airflow/.local/lib/python3.7/site-packages/airflow/models/taskinstance.py", line 1383, in _run_raw_task
    self._execute_task_with_callbacks(context, test_mode)
  File "/home/airflow/.local/lib/python3.7/site-packages/airflow/models/taskinstance.py", line 1502, in _execute_task_with_callbacks
    task_orig = self.render_templates(context=context)
  File "/home/airflow/.local/lib/python3.7/site-packages/airflow/models/taskinstance.py", line 2123, in render_templates
    original_task.render_template_fields(context)
  File "/home/airflow/.local/lib/python3.7/site-packages/airflow/models/baseoperator.py", line 1179, in render_template_fields
    self._do_render_template_fields(self, self.template_fields, context, jinja_env, set())
  File "/home/airflow/.local/lib/python3.7/site-packages/airflow/utils/session.py", line 75, in wrapper
    return func(*args, session=session, **kwargs)
  File "/home/airflow/.local/lib/python3.7/site-packages/airflow/models/abstractoperator.py", line 607, in _do_render_template_fields
    seen_oids,
  File "/home/airflow/.local/lib/python3.7/site-packages/airflow/models/abstractoperator.py", line 665, in render_template
    return render_template_to_string(template, context)
  File "/home/airflow/.local/lib/python3.7/site-packages/airflow/utils/helpers.py", line 288, in render_template_to_string
    return render_template(template, cast(MutableMapping[str, Any], context), native=False)
  File "/home/airflow/.local/lib/python3.7/site-packages/airflow/utils/helpers.py", line 283, in render_template
    return "".join(nodes)
  File "<template>", line 14, in root
  File "/home/airflow/.local/lib/python3.7/site-packages/jinja2/runtime.py", line 852, in _fail_with_undefined_error
    raise self._undefined_exception(self._undefined_message)
jinja2.exceptions.UndefinedError: 'dt' is undefined
[2023-04-07T13:37:58.670+0000] {taskinstance.py:1332} INFO - Marking task as UP_FOR_RETRY. dag_id=dag_with_posgres_operator_v02, task_id=insert_into_table, execution_date=20230401T000000, start_date=20230407T133758, end_date=20230407T133758
[2023-04-07T13:37:58.686+0000] {standard_task_runner.py:105} ERROR - Failed to execute job 6819 for task insert_into_table ('dt' is undefined; 1599)
[2023-04-07T13:37:58.695+0000] {local_task_job.py:212} INFO - Task exited with return code 1
[2023-04-07T13:37:58.732+0000] {taskinstance.py:2596} INFO - 0 downstream tasks scheduled from follow-on schedule check
