[2023-04-07T13:30:45.846+0000] {taskinstance.py:1090} INFO - Dependencies all met for dep_context=non-requeueable deps ti=<TaskInstance: dag_with_posgres_operator_v01.create_postgres_table manual__2023-04-07T13:29:32.977897+00:00 [queued]>
[2023-04-07T13:30:45.856+0000] {taskinstance.py:1090} INFO - Dependencies all met for dep_context=requeueable deps ti=<TaskInstance: dag_with_posgres_operator_v01.create_postgres_table manual__2023-04-07T13:29:32.977897+00:00 [queued]>
[2023-04-07T13:30:45.856+0000] {taskinstance.py:1288} INFO - 
--------------------------------------------------------------------------------
[2023-04-07T13:30:45.856+0000] {taskinstance.py:1289} INFO - Starting attempt 2 of 7
[2023-04-07T13:30:45.856+0000] {taskinstance.py:1290} INFO - 
--------------------------------------------------------------------------------
[2023-04-07T13:30:45.880+0000] {taskinstance.py:1309} INFO - Executing <Task(PostgresOperator): create_postgres_table> on 2023-04-07 13:29:32.977897+00:00
[2023-04-07T13:30:45.883+0000] {standard_task_runner.py:55} INFO - Started process 1266 to run task
[2023-04-07T13:30:45.885+0000] {standard_task_runner.py:82} INFO - Running: ['***', 'tasks', 'run', 'dag_with_posgres_operator_v01', 'create_postgres_table', 'manual__2023-04-07T13:29:32.977897+00:00', '--job-id', '6798', '--raw', '--subdir', 'DAGS_FOLDER/dag_with_postgres_operator.py', '--cfg-path', '/tmp/tmpqwalnql0']
[2023-04-07T13:30:45.886+0000] {standard_task_runner.py:83} INFO - Job 6798: Subtask create_postgres_table
[2023-04-07T13:30:45.936+0000] {task_command.py:389} INFO - Running <TaskInstance: dag_with_posgres_operator_v01.create_postgres_table manual__2023-04-07T13:29:32.977897+00:00 [running]> on host ce9c8327347b
[2023-04-07T13:30:46.017+0000] {taskinstance.py:1518} INFO - Exporting the following env vars:
AIRFLOW_CTX_DAG_OWNER=dejan
AIRFLOW_CTX_DAG_ID=dag_with_posgres_operator_v01
AIRFLOW_CTX_TASK_ID=create_postgres_table
AIRFLOW_CTX_EXECUTION_DATE=2023-04-07T13:29:32.977897+00:00
AIRFLOW_CTX_TRY_NUMBER=2
AIRFLOW_CTX_DAG_RUN_ID=manual__2023-04-07T13:29:32.977897+00:00
[2023-04-07T13:30:46.017+0000] {sql.py:254} INFO - Executing: 
            create table if not exists dag_runs (
                dt date,
                dag_id character varying,
                primary key (dt, dag_id)
            )
        
[2023-04-07T13:30:46.024+0000] {base.py:73} INFO - Using connection ID 'postgres_localhost' for task execution.
[2023-04-07T13:30:46.349+0000] {base.py:73} INFO - Using connection ID 'postgres_localhost' for task execution.
[2023-04-07T13:30:46.350+0000] {taskinstance.py:1776} ERROR - Task failed with exception
Traceback (most recent call last):
  File "/home/airflow/.local/lib/python3.7/site-packages/airflow/providers/common/sql/operators/sql.py", line 266, in execute
    **extra_kwargs,
  File "/home/airflow/.local/lib/python3.7/site-packages/airflow/providers/common/sql/hooks/sql.py", line 342, in run
    with closing(self.get_conn()) as conn:
  File "/home/airflow/.local/lib/python3.7/site-packages/airflow/providers/postgres/hooks/postgres.py", line 144, in get_conn
    self.conn = psycopg2.connect(**conn_args)
  File "/home/airflow/.local/lib/python3.7/site-packages/psycopg2/__init__.py", line 122, in connect
    conn = _connect(dsn, connection_factory=connection_factory, **kwasync)
psycopg2.OperationalError: connection to server at "localhost" (127.0.0.1), port 5432 failed: Connection refused
	Is the server running on that host and accepting TCP/IP connections?
connection to server at "localhost" (::1), port 5432 failed: Cannot assign requested address
	Is the server running on that host and accepting TCP/IP connections?

[2023-04-07T13:30:46.357+0000] {taskinstance.py:1332} INFO - Marking task as UP_FOR_RETRY. dag_id=dag_with_posgres_operator_v01, task_id=create_postgres_table, execution_date=20230407T132932, start_date=20230407T133045, end_date=20230407T133046
[2023-04-07T13:30:46.368+0000] {standard_task_runner.py:105} ERROR - Failed to execute job 6798 for task create_postgres_table (connection to server at "localhost" (127.0.0.1), port 5432 failed: Connection refused
	Is the server running on that host and accepting TCP/IP connections?
connection to server at "localhost" (::1), port 5432 failed: Cannot assign requested address
	Is the server running on that host and accepting TCP/IP connections?
; 1266)
[2023-04-07T13:30:46.388+0000] {local_task_job.py:212} INFO - Task exited with return code 1
[2023-04-07T13:30:46.430+0000] {taskinstance.py:2596} INFO - 0 downstream tasks scheduled from follow-on schedule check
